<?xml version="1.0" encoding="utf-8"?>
<mujoco model="car_empty_walled">
  <option timestep="0.002" integrator="implicitfast" cone="elliptic" iterations="100" gravity="0 0 -9.81"/>
  <default>
    <geom density="1"/>
  </default>
  <asset>
    <texture builtin="gradient" height="3072" rgb1="0.3 0.5 0.7" rgb2="0 0 0" type="skybox" width="512"/>
    <texture builtin="checker" height="300" mark="edge" markrgb="0.8 0.8 0.8" name="groundplane" rgb1="0.2 0.3 0.4" rgb2="0.1 0.2 0.3" type="2d" width="300"/>
    <material name="groundplane" reflectance="0.2" texrepeat="5 5" texture="groundplane" texuniform="true"/>
  </asset>
  <worldbody>
    <light dir="0 0 -1" directional="true" pos="0 0 1.5"/>
    <geom condim="4" friction="0.5 0.005 0.001" material="groundplane" name="floor" size="0 0 0.05" type="plane"/>
    <body name="walls">
      <geom name="wall_north" condim="4" pos="0 0.5 0.08" rgba="0.8 0.8 0.8 1" size="0.5 0.01 0.08" type="box"/>
      <geom name="wall_south" condim="4" pos="0 -0.5 0.08" rgba="0.8 0.8 0.8 1" size="0.5 0.01 0.08" type="box"/>
      <geom name="wall_east" condim="4" pos="0.5 0 0.08" rgba="0.8 0.8 0.8 1" size="0.01 0.5 0.08" type="box"/>
      <geom name="wall_west" condim="4" pos="-0.5 0 0.08" rgba="0.8 0.8 0.8 1" size="0.01 0.5 0.08" type="box"/>
    </body>

    <!-- Single movable object near the center -->
    <body name="obstacle_1_movable">
      <geom name="obstacle_1_movable" condim="4" pos="0.10 0.10 0.035" euler="0 0 0"
            friction="1.0 0.005 0.001" rgba="1 1 0 1" size="0.040 0.040 0.035" type="box" mass="0.1"/>
      <joint type="free"/>
    </body>

    <!-- Goal site at the opposite side so the robot has a reason to push -->
    <site name="goal" pos="-0.30 -0.30 0.0" rgba="0 1 0 0.3" size="0.03" type="sphere"/>

    <!-- Diff-drive car body at a corner -->
    <body name="car" pos="-0.30 0.30 0.010">
      <freejoint name="car_freejoint"/>
      <inertial pos="0.0 0 0.0375" mass="0.35" diaginertia="0.000266 0.000266 0.000286"/>
      <geom name="front_chassis_collision" type="box" pos="0.0175 0 0.0375"
            size="0.0175 0.035 0.0325" rgba="0.3 0.3 0.7 1"/>
      <geom name="rear_chassis_collision" type="box" pos="-0.0175 0 0.0375"
            size="0.0175 0.035 0.0325" rgba="0.25 0.25 0.6 1"/>
      <geom name="front_marker" type="box" pos="0.034 0 0.0505"
            size="0.002 0.015 0.010" rgba="1.0 0.2 0.2 1" contype="0" conaffinity="0"/>

      <body name="rear_support_body" pos="-0.030 0.0 0.0025">
        <joint name="rear_caster_joint" type="ball" damping="0.0001"/>
        <inertial pos="0 0 0" mass="0.025" diaginertia="0.000001 0.000001 0.000001"/>
        <geom name="rear_support" type="sphere" pos="0 0 0" size="0.0025"
              friction="0.0 0.0 0.0" rgba="0.7 0.1 0.1 1"/>
      </body>
      <body name="front_support_body" pos="0.030 0.0 0.0025">
        <joint name="front_caster_joint" type="ball" damping="0.0001"/>
        <inertial pos="0 0 0" mass="0.025" diaginertia="0.000001 0.000001 0.000001"/>
        <geom name="front_support" type="sphere" pos="0 0 0" size="0.0025"
              friction="0.0 0.0 0.0" rgba="0.1 0.7 0.1 1"/>
      </body>

      <body name="left_wheel" pos="0.0 0.0375 0.015">
        <inertial pos="0 0 0" mass="0.05" diaginertia="0.000003 0.000006 0.000003"/>
        <joint name="left_wheel_joint" type="hinge" axis="0 1 0"/>
        <geom name="left_wheel_collision" type="cylinder" size="0.015 0.0005"
              euler="90 0 0" rgba="0.1 0.1 0.1 1"/>
      </body>
      <body name="right_wheel" pos="0.0 -0.0375 0.015">
        <inertial pos="0 0 0" mass="0.05" diaginertia="0.000003 0.000006 0.000003"/>
        <joint name="right_wheel_joint" type="hinge" axis="0 1 0"/>
        <geom name="right_wheel_collision" type="cylinder" size="0.015 0.0005"
              euler="90 0 0" rgba="0.1 0.1 0.1 1"/>
      </body>
    </body>
  </worldbody>
  <actuator>
    <velocity name="left_wheel_drive" joint="left_wheel_joint"
              ctrlrange="-25.0 25.0" kv="0.75" forcerange="-0.3 0.3"/>
    <velocity name="right_wheel_drive" joint="right_wheel_joint"
              ctrlrange="-25.0 25.0" kv="0.75" forcerange="-0.3 0.3"/>
  </actuator>
</mujoco>
